<?xml version="1.0" ?>
<!-- =================================================================================== -->
<!-- |    This document was autogenerated by xacro from omronld.urdf.xacro             | -->
<!-- |    EDITING THIS FILE BY HAND IS NOT RECOMMENDED                                 | -->
<!-- =================================================================================== -->
<robot name="omronld" xmlns:controller="http://playerstage.sourceforge.net/gazebo/xmlschema/#controller" xmlns:interface="http://playerstage.sourceforge.net/gazebo/xmlschema/#interface" xmlns:sensor="http://playerstage.sourceforge.net/gazebo/xmlschema/#sensor" xmlns:xacro="http://ros.org/wiki/xacro">
  <!--general-->
  <!--wheels-->
  <!-- LASER -->
  <!-- base_link origin point is center of rotation, on the floor. -->
  <link name="base_link">
    <inertial>
      <mass value="63.5664"/>
      <!-- kg -->
      <inertia ixx="3.1802" ixy="0" ixz="0" iyy="2.9908" iyz="0" izz="2.2912"/>
    </inertial>
    <visual>
      <geometry name="base_link_visual_geom">
        <mesh filename="package://omronld_description/meshes/omronld_visual.stl" scale="0.001 0.001 0.001"/>
      </geometry>
      <origin rpy="1.570795 0 1.570795" xyz="-0.000880947 0 0.0876498"/>
    </visual>
    <collision name="base_link_collision">
      <geometry name="base_link_collision_geom">
        <box size="0.7 0.5 0.05"/>
      </geometry>
      <origin rpy="0 0 0" xyz="0 0 0.1"/>
    </collision>
  </link>
  <!-- omronld wheel macros -->
  <link name="left_wheel_link">
    <inertial>
      <mass value="1.1"/>
      <origin xyz="0 0 0"/>
      <inertia ixx="0.02" ixy="0" ixz="0" iyy="0.02" iyz="0" izz="0.01"/>
    </inertial>
    <collision>
      <origin rpy="1.570795 0 0" xyz="0 0 0"/>
      <geometry>
        <cylinder length="0.048" radius="0.09684315"/>
      </geometry>
    </collision>
  </link>
  <gazebo reference="left_wheel_link">
    <!--http://wiki.ros.org/urdf/Tutorials/Adding%20Physical%20and%20Collision%20Properties%20to%20a%20URDF%20Model-->
    <mu1 value="100.0"/>
    <mu2 value="100.0"/>
    <kp value="10000000.0"/>
    <kd value="1.0"/>
    <fdir1 value="1 0 0"/>
  </gazebo>
  <joint name="left_wheel" type="continuous">
    <parent link="base_link"/>
    <child link="left_wheel_link"/>
    <origin rpy="0 0 0" xyz="0.0 0.19648885 0.09684315"/>
    <axis rpy="0 0 0" xyz="0 1 0"/>
    <joint_properties damping="1.0" friction="10.0"/>
  </joint>
  <transmission name="left_wheel_trans" type="SimpleTransmission">
    <type>transmission_interface/SimpleTransmission</type>
    <actuator name="left_wheel_motor">
      <mechanicalReduction>1</mechanicalReduction>
    </actuator>
    <joint name="left_wheel">
      <hardwareInterface>hardware_interface/EffortJointInterface</hardwareInterface>
    </joint>
  </transmission>
  <link name="right_wheel_link">
    <inertial>
      <mass value="1.1"/>
      <origin xyz="0 0 0"/>
      <inertia ixx="0.02" ixy="0" ixz="0" iyy="0.02" iyz="0" izz="0.01"/>
    </inertial>
    <collision>
      <origin rpy="1.570795 0 0" xyz="0 0 0"/>
      <geometry>
        <cylinder length="0.048" radius="0.09684315"/>
      </geometry>
    </collision>
  </link>
  <gazebo reference="right_wheel_link">
    <!--http://wiki.ros.org/urdf/Tutorials/Adding%20Physical%20and%20Collision%20Properties%20to%20a%20URDF%20Model-->
    <mu1 value="100.0"/>
    <mu2 value="100.0"/>
    <kp value="10000000.0"/>
    <kd value="1.0"/>
    <fdir1 value="1 0 0"/>
  </gazebo>
  <joint name="right_wheel" type="continuous">
    <parent link="base_link"/>
    <child link="right_wheel_link"/>
    <origin rpy="0 0 0" xyz="0.0 -0.19648885 0.09684315"/>
    <axis rpy="0 0 0" xyz="0 1 0"/>
    <joint_properties damping="1.0" friction="10.0"/>
  </joint>
  <transmission name="right_wheel_trans" type="SimpleTransmission">
    <type>transmission_interface/SimpleTransmission</type>
    <actuator name="right_wheel_motor">
      <mechanicalReduction>1</mechanicalReduction>
    </actuator>
    <joint name="right_wheel">
      <hardwareInterface>hardware_interface/EffortJointInterface</hardwareInterface>
    </joint>
  </transmission>
  <!-- LASER -->
  <link name="base_laser">
    <inertial>
      <mass value="1.1"/>
      <origin xyz="0 0 0"/>
      <inertia ixx="0.00307156543804" ixy="0.0" ixz="0.0" iyy="0.00312849041527" iyz="0.0" izz="0.00196432421427"/>
    </inertial>
    <visual>
      <origin rpy="0 0 0" xyz="0 0 0"/>
      <geometry>
        <!-- Origin of this mesh is the focal point of the LIDAR. -->
        <mesh filename="package://omronld_description/meshes/laser/sick-lms1xx.dae"/>
      </geometry>
    </visual>
    <collision>
      <origin rpy="0 0 0" xyz="0 0 -0.05"/>
      <geometry>
        <box size="0.105 0.1 0.1"/>
      </geometry>
    </collision>
  </link>
  <joint name="base_laser_joint" type="fixed">
    <origin rpy="3.14159 0.0 0.0" xyz="0.2652 0.0 0.201"/>
    <parent link="base_link"/>
    <child link="base_laser"/>
  </joint>
  <gazebo reference="base_laser">
    <turnGravityOff>false</turnGravityOff>
    <sensor name="base_laser" type="ray">
      <pose>0 0 0 0 0 0</pose>
      <visualize>false</visualize>
      <update_rate>50</update_rate>
      <ray>
        <scan>
          <horizontal>
            <samples>720</samples>
            <resolution>1</resolution>
            <min_angle>-2.0944</min_angle>
            <max_angle>2.0944</max_angle>
          </horizontal>
        </scan>
        <range>
          <min>0.1</min>
          <max>15</max>
          <resolution>0.01</resolution>
        </range>
        <noise>
          <type>gaussian</type>
          <mean>0.0</mean>
          <stddev>0.001</stddev>
        </noise>
      </ray>
      <plugin filename="libgazebo_ros_laser.so" name="gazebo_ros_laser">
        <topicName>scan</topicName>
        <frameName>base_laser</frameName>
      </plugin>
    </sensor>
  </gazebo>
  <link name="base_laser_fake">
    <inertial>
      <mass value="1.1"/>
      <origin xyz="0 0 0"/>
      <inertia ixx="0.00307156543804" ixy="0.0" ixz="0.0" iyy="0.00312849041527" iyz="0.0" izz="0.00196432421427"/>
    </inertial>
    <visual>
      <origin rpy="0 0 0" xyz="0 0 0"/>
      <geometry>
        <!-- Origin of this mesh is the focal point of the LIDAR. -->
        <mesh filename="package://omronld_description/meshes/laser/sick-lms1xx.dae"/>
      </geometry>
    </visual>
    <collision>
      <origin rpy="0 0 0" xyz="0 0 -0.05"/>
      <geometry>
        <box size="0.105 0.1 0.1"/>
      </geometry>
    </collision>
  </link>
  <joint name="base_laser_fake_joint" type="fixed">
    <origin rpy="-3.14159 0.0 0.0" xyz="-0.2652 0.0 0.201"/>
    <parent link="base_link"/>
    <child link="base_laser_fake"/>
  </joint>
  <gazebo reference="base_laser_fake">
    <turnGravityOff>false</turnGravityOff>
    <sensor name="base_laser_fake" type="ray">
      <pose>0 0 0 0 0 0</pose>
      <visualize>false</visualize>
      <update_rate>50</update_rate>
      <ray>
        <scan>
          <horizontal>
            <samples>720</samples>
            <resolution>1</resolution>
            <min_angle>-2.0944</min_angle>
            <max_angle>2.0944</max_angle>
          </horizontal>
        </scan>
        <range>
          <min>0.1</min>
          <max>15</max>
          <resolution>0.01</resolution>
        </range>
        <noise>
          <type>gaussian</type>
          <mean>0.0</mean>
          <stddev>0.001</stddev>
        </noise>
      </ray>
      <plugin filename="libgazebo_ros_laser.so" name="gazebo_ros_laser">
        <topicName>scanFake</topicName>
        <frameName>base_laser_fake</frameName>
      </plugin>
    </sensor>
  </gazebo>
  <!-- GAZEBO PLUGINS-->
  <!-- http://wiki.ros.org/urdf/Tutorials/Using%20a%20URDF%20in%20Gazebo-->
  <gazebo>
    <plugin filename="libgazebo_ros_control.so" name="gazebo_ros_control">
      <legacyModeNS>false</legacyModeNS>
      <robotParam>/omronld_description</robotParam>
    </plugin>
  </gazebo>
  <gazebo>
    <plugin filename="libgazebo_ros_diff_drive.so" name="differential_drive_controller">
      <rosDebugLevel>Debug</rosDebugLevel>
      <legacyMode>false</legacyMode>
      <publishWheelTF>false</publishWheelTF>
      <robotNamespace>/</robotNamespace>
      <publishTf>1</publishTf>
      <publishWheelJointState>true</publishWheelJointState>
      <alwaysOn>true</alwaysOn>
      <updateRate>100.0</updateRate>
      <leftJoint>left_wheel</leftJoint>
      <rightJoint>right_wheel</rightJoint>
      <wheelSeparation>0.3929777</wheelSeparation>
      <wheelDiameter>0.1936863</wheelDiameter>
      <broadcastTF>1</broadcastTF>
      <wheelTorque>100</wheelTorque>
      <wheelAcceleration>1.8</wheelAcceleration>
      <commandTopic>cmd_vel</commandTopic>
      <odometryFrame>odom</odometryFrame>
      <odometryTopic>odom</odometryTopic>
      <robotBaseFrame>base_link</robotBaseFrame>
    </plugin>
  </gazebo>
  <!-- four passive caster  -->
  <link name="r_f_caster_caster_link">
    <inertial>
      <mass value="0.05"/>
      <origin xyz="0 0 0"/>
      <inertia ixx="0.01" ixy="0" ixz="0" iyy="0.01" iyz="0" izz="0.01"/>
    </inertial>
    <collision>
      <origin rpy="1.570795 0 0" xyz="0 0 0"/>
      <geometry>
        <cylinder length="0.03175" radius="0.0375"/>
      </geometry>
    </collision>
    <visual>
      <origin rpy="1.570795 0 0" xyz="0 0 0"/>
      <geometry>
        <cylinder length="0.03175" radius="0.0375"/>
      </geometry>
    </visual>
  </link>
  <joint name="r_f_caster_caster" type="fixed">
    <parent link="base_link"/>
    <child link="r_f_caster_caster_link"/>
    <axis rpy="0 0 0" xyz="0 0 1"/>
    <origin rpy="0 0 0" xyz="0.2076340 -0.10795 0.0375"/>
  </joint>
  <link name="l_f_caster_caster_link">
    <inertial>
      <mass value="0.05"/>
      <origin xyz="0 0 0"/>
      <inertia ixx="0.01" ixy="0" ixz="0" iyy="0.01" iyz="0" izz="0.01"/>
    </inertial>
    <collision>
      <origin rpy="1.570795 0 0" xyz="0 0 0"/>
      <geometry>
        <cylinder length="0.03175" radius="0.0375"/>
      </geometry>
    </collision>
    <visual>
      <origin rpy="1.570795 0 0" xyz="0 0 0"/>
      <geometry>
        <cylinder length="0.03175" radius="0.0375"/>
      </geometry>
    </visual>
  </link>
  <joint name="l_f_caster_caster" type="fixed">
    <parent link="base_link"/>
    <child link="l_f_caster_caster_link"/>
    <axis rpy="0 0 0" xyz="0 0 1"/>
    <origin rpy="0 0 0" xyz="0.2076340 0.10795 0.0375"/>
  </joint>
  <link name="r_b_caster_caster_link">
    <inertial>
      <mass value="0.05"/>
      <origin xyz="0 0 0"/>
      <inertia ixx="0.01" ixy="0" ixz="0" iyy="0.01" iyz="0" izz="0.01"/>
    </inertial>
    <collision>
      <origin rpy="1.570795 0 0" xyz="0 0 0"/>
      <geometry>
        <cylinder length="0.03175" radius="0.0375"/>
      </geometry>
    </collision>
    <visual>
      <origin rpy="1.570795 0 0" xyz="0 0 0"/>
      <geometry>
        <cylinder length="0.03175" radius="0.0375"/>
      </geometry>
    </visual>
  </link>
  <joint name="r_b_caster_caster" type="fixed">
    <parent link="base_link"/>
    <child link="r_b_caster_caster_link"/>
    <axis rpy="0 0 0" xyz="0 0 1"/>
    <origin rpy="0 0 0" xyz="-0.2287113 -0.15664945 0.0375"/>
  </joint>
  <link name="l_b_caster_caster_link">
    <inertial>
      <mass value="0.05"/>
      <origin xyz="0 0 0"/>
      <inertia ixx="0.01" ixy="0" ixz="0" iyy="0.01" iyz="0" izz="0.01"/>
    </inertial>
    <collision>
      <origin rpy="1.570795 0 0" xyz="0 0 0"/>
      <geometry>
        <cylinder length="0.03175" radius="0.0375"/>
      </geometry>
    </collision>
    <visual>
      <origin rpy="1.570795 0 0" xyz="0 0 0"/>
      <geometry>
        <cylinder length="0.03175" radius="0.0375"/>
      </geometry>
    </visual>
  </link>
  <joint name="l_b_caster_caster" type="fixed">
    <parent link="base_link"/>
    <child link="l_b_caster_caster_link"/>
    <axis rpy="0 0 0" xyz="0 0 1"/>
    <origin rpy="0 0 0" xyz="-0.2287113 0.15664945 0.0375"/>
  </joint>
</robot>

