<?xml version="1.0"?>
<robot  xmlns:sensor="http://playerstage.sourceforge.net/gazebo/xmlschema/#sensor"
	xmlns:controller="http://playerstage.sourceforge.net/gazebo/xmlschema/#controller"
	xmlns:interface="http://playerstage.sourceforge.net/gazebo/xmlschema/#interface"
        xmlns:xacro="http://www.ros.org/wiki/xacro"
	name="wsg_50">

<!-- finger_length: Length of finger from gripper base. (was 0.023) -->
<!-- finger_tip:    Offset of finger tip along fingers' motion direction.
                    Use e.g. for single contact point tip on finger. (default 0) -->

<xacro:macro name="wsg_50_xacro" params="name parent gripperHwInterface *origin">
 <joint name="${name}_anterior_gripper_joint" type="fixed">
    <xacro:insert_block name="origin"/>
    <parent link="${parent}"/>
    <child link="${name}_base_link"/>
 </joint>

<!-- BASE LINK -->
 <link name="${name}_base_link">
      <inertial>
          <mass value="1.15"/>
          <origin xyz="0 0 0" />
     	  <!--inertia ixx="1.0" ixy="0.0" ixz="0.0"
               iyy="100.0" iyz="0.0" 
               izz="1.0" /-->
      	  <inertia  ixx="1.0" ixy="0.0"  ixz="0.0"  iyy="1.0"  iyz="0.0"  izz="1.0" />
      </inertial>
      <visual>
          <origin xyz="0.0 0 0" rpy="0 0 0" />
          <geometry>
             <mesh filename="package://wsg_50_simulation/meshes/WSG50_110.stl" scale="1 1 1"/>
	     <!--box size="0.146 0.05 0.0735"/-->
          </geometry>
          <material name="grey">
		<color rgba="0.5 0.5 0.5 1"/>
      	  </material>
      </visual>

      <collision>
          <origin xyz="0.0 0 0" rpy="0 0 0" />
          <geometry>
	     <!--box size="0.146 0.05 0.0735"/-->
             <mesh filename="package://wsg_50_simulation/meshes/WSG50_110.stl" scale="1 1 1"/>
         </geometry>
     </collision>
  </link>

  <gazebo reference="${name}_base_link">
    <material>Gazebo/Grey</material>
    <turnGravityOff>false</turnGravityOff>
  </gazebo>

  <!-- GRIPPER LEFT -->
  <joint name="${name}_gripper_left_joint" type="prismatic">
     <limit lower="-0.055" upper="-0.0027" effort="1.0" velocity="1.0"/>
     <origin xyz="0 0 0" rpy="0 0 0" />      <!--origin xyz="-0.0067 0 0.049" rpy="0 0 0" /-->
     <parent link="${name}_base_link"/>
     <child link="${name}_gripper_left" />
     <dynamics friction="0.1" damping="0.1" />
     <axis xyz="1 0 0"/>
     <limit effort="100" velocity="100"/>
  </joint>

  <transmission name="${name}_base_trans_left">
     <type>transmission_interface/SimpleTransmission</type>
     <actuator name="${name}_base_motor_left">
       <hardwareInterface>hardware_interface/${gripperHwInterface}</hardwareInterface>
       <mechanicalReduction>1</mechanicalReduction>
       <!--motorTorqueConstant>1</motorTorqueConstant-->
     </actuator>
     <joint name="${name}_gripper_left_joint">
      <hardwareInterface>hardware_interface/${gripperHwInterface}</hardwareInterface>
     </joint>
  </transmission>

  <link name="${name}_gripper_left">
      <inertial>
          <mass value="0.1" />
          <origin xyz="0 0 0" />
      <inertia ixx="1.0" ixy="0.0" ixz="0.0"
               iyy="1.0" iyz="0.0" 
               izz="1.0" />
      </inertial>

      <visual>
          <origin xyz="0.0 0 0" rpy="0 0 0" />
          <geometry>
             <mesh filename="package://wsg_50_simulation/meshes/GUIDE_WSG50_110.dae" scale="0.001 0.001 0.001"/>
	     <!--box size="0.0175 0.03 0.024"/-->
          </geometry>
          <material name="black">
		<color rgba="0 0 0 0"/>
      	  </material>
      </visual>

      <collision>
          <origin xyz="0 0 0" rpy="0 0 0" />
          <geometry>
	     <!--box size="0.0175 0.03 0.024"/-->
             <mesh filename="package://wsg_50_simulation/meshes/GUIDE_WSG50_110.dae" scale="0.001 0.001 0.001"/>
         </geometry>
     </collision>
     <contact_coefficients kd="1.0" kp="1000.0" mu="0"/>
  </link>

  <gazebo reference="${name}_gripper_left">
    <material>Gazebo/Blue</material>
    <turnGravityOff>false</turnGravityOff>
  </gazebo>


  <!-- GRIPPER RIGHT -->

  <joint name="${name}_gripper_right_joint" type="prismatic">
     <limit lower="0.0027" upper="0.055" effort="1.0" velocity="1.0"/>
     <origin xyz="0 0 0" rpy="0 0 3.14159" />
     <parent link="${name}_base_link"/>
     <child link="${name}_gripper_right" />
     <axis xyz="-1 0 0"/>
     <dynamics friction="0.1" damping="0.1" />
     <limit effort="100" velocity="100"/>
  </joint>

  <transmission name="${name}_base_trans_right">
     <type>transmission_interface/SimpleTransmission</type>
     <actuator name="${name}_base_motor_right">
        <hardwareInterface>hardware_interface/${gripperHwInterface}</hardwareInterface>
        <mechanicalReduction>1</mechanicalReduction>
       <!--motorTorqueConstant>1</motorTorqueConstant-->
     </actuator>
     <joint name="${name}_gripper_right_joint">
        <hardwareInterface>hardware_interface/${gripperHwInterface}</hardwareInterface>
     </joint>
  </transmission>
	
    <link name="${name}_gripper_right">
      <inertial>
          <mass value="0.1" />
          <origin xyz="0 0 0" />
      <inertia ixx="1.0" ixy="0.0" ixz="0.0"
               iyy="1.0" iyz="0.0" 
               izz="1.0" />
      </inertial>

      <visual>
          <origin xyz="0.0 0 0" rpy="0 0 0" />
          <geometry>
             <mesh filename="package://wsg_50_simulation/meshes/GUIDE_WSG50_110.dae" scale="0.001 0.001 0.001"/>
	     <!--box size="0.0175 0.03 0.024"/-->
          </geometry>
          <material name="black">
		<color rgba="0 0 0 0"/>
      	  </material>
      </visual>

      <collision>
          <origin xyz="0 0 0" rpy="0 0 0" />
          <geometry>
	     <!--box size="0.0175 0.03 0.024"/-->
             <mesh filename="package://wsg_50_simulation/meshes/GUIDE_WSG50_110.dae" scale="0.001 0.001 0.001"/>
         </geometry>
     </collision>
     <contact_coefficients kd="1.0" kp="1000.0" mu="0"/>
  </link>

  <gazebo reference="gripper_right">
    <material>Gazebo/White</material>
    <turnGravityOff>false</turnGravityOff>
  </gazebo>


<!-- <gazebo>
  <plugin name="gazebo_ros_control" filename="libgazebo_ros_control.so">
    <robotNamespace>/</robotNamespace>
  </plugin>
</gazebo>

  <gazebo>
    <controller:gazebo_ros_controller_manager name="gazebo_ros_controller_manager" plugin="libgazebo_ros_controller_manager.so">
      <alwaysOn>true</alwaysOn>
      <updateRate>1000.0</updateRate>
      <interface:audio name="gazebo_ros_controller_manager_dummy_iface" />
    </controller:gazebo_ros_controller_manager>
  </gazebo> -->

</xacro:macro>

</robot>

