<?xml version="1.0"?>

<robot
  xmlns:sensor="http://playerstage.sourceforge.net/gazebo/xmlschema/#sensor"
  xmlns:controller="http://playerstage.sourceforge.net/gazebo/xmlschema/#controller"
  xmlns:interface="http://playerstage.sourceforge.net/gazebo/xmlschema/#interface"
  xmlns:xacro="http://ros.org/wiki/xacro"
  >

  <!-- Right/Left Wheel -->
  <xacro:macro name="omronld_wheel" params="wheel_prefix *joint_pose">

    	<link name="${wheel_prefix}_wheel_link">

    		<inertial>
      			<mass value="1.1"/>
      			<origin xyz="0 0 0"/>
      			<inertia ixx="0.02" ixy="0" ixz="0" iyy="0.02" iyz="0" izz="0.01" />
      		</inertial>

    		<collision>
			<origin xyz="0 0 0" rpy="${M_PI/2} 0 0" />
			<geometry>
				<cylinder length="${wheel_length}" radius="${wheel_radius}" />
			</geometry>
		</collision>

  </link>

	<gazebo reference="${wheel_prefix}_wheel_link">  <!--http://wiki.ros.org/urdf/Tutorials/Adding%20Physical%20and%20Collision%20Properties%20to%20a%20URDF%20Model-->

		<mu1 value="100.0"/>
		<mu2 value="100.0"/>
		<kp value="10000000.0" />
		<kd value="1.0" />
		<fdir1 value="1 0 0"/>

	</gazebo>

  	<joint name="${wheel_prefix}_wheel" type="continuous">
    		<parent link="base_link"/>
    		<child link="${wheel_prefix}_wheel_link"/>
		<xacro:insert_block name="joint_pose"/>
		<axis xyz="0 1 0" rpy="0 0 0" />

		<joint_properties damping="1.0" friction="10.0"/>

  	</joint>

	<transmission name="${wheel_prefix}_wheel_trans" type="SimpleTransmission">
		<type>transmission_interface/SimpleTransmission</type>
		<actuator name="${wheel_prefix}_wheel_motor">
			<mechanicalReduction>1</mechanicalReduction>
		</actuator>
		<joint name="${wheel_prefix}_wheel">
			<hardwareInterface>hardware_interface/VelocityJointInterface</hardwareInterface>
		</joint>
	</transmission>

   </xacro:macro>

</robot>
